import datetime

def error_log(type, details) -> str:
    pass

class rand_rp:
    def __init__(self, *args, **kwargs):
        pass

    def file_err(target):
        return

    def arr_err():
        return "```内部でエラーが発生した為、正常に処理を実行できませんでした```"